# 为什么要用 nodejs 写后端？

* 学习成本低：nodeJs是一个基于Chrome V8引擎的 JavaScript 运行环境，方便于前端开发学习，相对于前端开发重新学习java、php，它是比较容易上手
* V8引擎是使用 C++ 编写，运行速度更快
* 基于事件驱动的非阻塞 I/O 模型，可以快速响应和处理并发请求

# nodejs 事件循环机制？



# nodejs 异常捕获如何处理？

Node.js 中异常的可能性多：普通异常，Promise 内异常，定时器内异常，Worker 内异常。

异常的处理方式也多种多样：try-catch 语句，全局事件，Worker 事件等。

Node.js 中有 `process.on("uncaughtException")`, `process.on("unhandledRejection")` 等 Event 来处理全局的异常事件。

## 普通的异常情况

这里的情况都非常的普通而简单，和其他编程语言无异，但事情将在后面变得复杂，让我们在此做一些铺垫。

简单来说，就是我们直接抛出一个异常，这样的异常无疑会直接终止程序的运行，我们检测程序是否还在运行的 `still running` 也没有输出。

```js
// simple.js
setInterval(() => {
    console.log('still running');
}, 500)

throw 'simple';

/*
throw 'simple';
^
simple
(Use `node --trace-uncaught ...` to show where the exception was thrown)
*/
```



### `try-catch` 与普通异常

这种情况也很普通，但还是让我们看看 `try-catch` 语句和简单异常组合的情况：可以看到，程序没有退出，正确运行，一切都和一般的编程语言类似。

```js
setInterval(() => {
    console.log('still running');
}, 500)


try {
    throw 'simple';
} catch(err) {
    console.log('catch', err);
}


/*
catch simple
still running
still running
still running
still running
*/
```

### `process.on("uncaughtException")` 与普通异常

我们用 Node.js 特有的 `uncaughtException` 事件来试图捕获一下抛出的异常。在这种情况下，我们未捕获的异常会触发 `uncaughtException` 捕获，由它的 callback 进行处理，并且我们可以看到，当使用了 `uncaughtException` 的情况下，程序是不会退出的。

```js
setInterval(() => {
    console.log('still running');
}, 500)


process.on('uncaughtException', (err) => {
    console.log('uncaught exception', err);
});

throw 'simple';

/*
uncaught exception simple
still running
still running
still running
still running
*/
```

## Promise 的异常情况

### `process.on("unhandledRejection")` 与 Promise 异常

```js
setInterval(() => { console.log('still running'); }, 500);

async function main() {
    throw 'async';
}

main();

process.on('unhandledRejection', (err) => {
    console.log('unhandled exception', err);
    throw err;
})

/*
unhandled exception async

/Users/wwwzbwcom/Downloads/test/test.js:11
    throw err;
    ^
async
*/
```

在 `unhandledRejection` 的事件回调函数中可以进行异常的捕获，并在此处将异常再次抛出，则需要再次进行 `throw`.

## 定时器回调内的异常情况

```js
setInterval(() => { console.log('still running'); }, 500);

setTimeout(() => {
    throw 'setTimeout';
}, 1000);

/*
still running

/Users/wwwzbwcom/Downloads/test/test.js:4
    throw 'setTimeout';
    ^
setTimeout
(Use `node --trace-uncaught ...` to show where the exception was thrown)
*/
```

它的回调中**产生的异常和 Promise 中的又不一致了**，其中的异常会直接抛出并导致程序直接终止。

### Promise 中定时器回调异常

- 当 Promise 内定时器回调抛出异常时，和普通异常一样，直接抛出顶层的 `uncaughtException`

综合来看，我们可以了解到

- 定时器回调的运行和定时器在哪定义无关
- **定时器中的异常机制和普通的异常机制是一样的**

```js
setInterval(() => { console.log('still running'); }, 500);

async function main() {
    setTimeout(() => {
        throw 'setTimeout in async';
    }, 1000);
}

main();

/*
still running

/Users/wwwzbwcom/Downloads/test/test.js:5
        throw 'setTimeout in main';
        ^
setTimeout in main
(Use `node --trace-uncaught ...` to show where the exception was thrown)
*/
```

### 定时器回调中的 Promise 异常

上面说到，定时器中的异常处理与普通的异常情况一致，故在定时器回调函数中的 async 函数异常，也是抛出 `unhandledRejection` 的事件：

```js
setInterval(() => { console.log('still running'); }, 500);

setTimeout(function () {
    main();
}, 1000);

async function main() {
    throw 'async in setTimeout'
}

/*
still running
(node:18741) UnhandledPromiseRejectionWarning: async in setTimeout
(Use `node --trace-warnings ...` to show where the warning was created)
(node:18741) UnhandledPromiseRejectionWarning: ...
still running
still running
*/
```

## Worker 内的异常情况

### Worker 内的普通异常

在 Worker 线程中抛出普通异常，我们可以看到：

- Worker 线程停止运行
- 主线程收到 Worker 线程发来的 `error` 事件
- **主线程不停止运行**

```js
const { Worker, isMainThread } = require('worker_threads');

if (isMainThread) {
		setInterval(() => { console.log('main still running'); }, 500);
    const worker = new Worker(__filename)
    worker.on('error', (err) => {
        console.log('worker error event: ' + err);
    });
} else {
    setInterval(() => { console.log('worker still running'); }, 500);
    throw 'worker error';
}

/*
worker error event: Error: Unhandled error. ('worker error')
main still running
main still running
main still running
main still running
*/
```

### Worker 内的 Promise 异常

Worker 内发生 Promise 异常时，和主线程发生异步异常是类似的，**Worker 线程不会终止，更不会导致程序终止**

```js
const { Worker, isMainThread } = require('worker_threads');


if (isMainThread) {
    setInterval(() => { console.log('main still running'); }, 500);
    const worker = new Worker(__filename)
    worker.on('error', (err) => {
        console.log('worker error event: ' + err);
    });
} else {
    setInterval(() => { console.log('worker still running'); }, 500);
    async function main() {
        throw 'worker async error';
    }
    main();
}

/*
(node:19866) UnhandledPromiseRejectionWarning: worker async error
(Use `node --trace-warnings ...` to show where the warning was created)
(node:19866) UnhandledPromiseRejectionWarning: ...
main still running
worker still running
main still running
worker still running
main still running
worker still running
*/
```

### Worker 内的定时器回调异常

这里和主线程定时器回调内发生异常也是类似的，**Worker 线程不会终止，更不会导致程序终止**

```js
const { Worker, isMainThread } = require('worker_threads');


if (isMainThread) {
    setInterval(() => { console.log('main still running'); }, 500);
    const worker = new Worker(__filename)
    worker.on('error', (err) => {
        console.log('worker error event: ' + err);
    });
} else {
    setInterval(() => { console.log('worker still running'); }, 500);
    setTimeout(() => {
        throw 'worker setTimeout error'
    }, 1000);
}

/*
main still running
worker still running
main still running
worker error event: worker setTimeout error
main still running
main still running
main still running
main still running
*/
```

## 总结

JavaScript 中的异步机制多种多样，有和其他变成语言类似的 `throw` 异常，还有异步事件中产生的异常等。

Node.js 的出现更引入了更多异常的情况，如 `Worker` 内产生的异常。也引入了更多异常的处理手段，包括 `process.on("uncaughtException")` 和 `process.on("unhandledRejection")`。
